Workbook

Sheet Reporte
A1: REPORTE DIARIO | S1: 1670 | T1: 27641.37 | U1: 1 al 3 | X1: 5 al 9 | AH1: REPORTE DIARIO
A2: Fecha | B2: h | C2: MINERAL (TMS) | D2: TORTA (TMS) | E2: S | F2: RM 1/2/3 DTT-100 S | G2: RM 1/2/3 DTT-100 S/F | H2: RM 5/6/7/8/9 DTT-100 S | I2: RM 5/6/7/8/9 DTT-100 S/F | J2: ESP.Ant Fe | K2: ESP.N Fe Sol | L2: ESP.Ant FeO | M2: ESP.N FeO | N2: Promedio de Fe Sol | O2: Promedio de FeO | P2: H2O | Q2: %RECUP. PESO | R2: RATIO | S2: Eficiencia Alimentación | T2: Eficiencia Concentrado | U2: Mediana | V2: Mayor | W2: Menor | X2: Mediana | Y2: Mayor | Z2: Menor | AA2: KPI S | AB2: KPI Fe | AC2: KPI FeO | AI2: 13360 | AJ2: Turno A | AK2: Turno B | AL2: Turno C | AM2: Día
A3: =+'CONTROL PROD.TORTA'!A105 -> 46269 | B3: 0.375 | C3: =+'CONTROL PROD.TORTA'!B106 -> 1430 | D3: =+'CONTROL PROD.TORTA'!C106 -> 923 | E3: =+'CONTROL PROD.TORTA'!D106 -> 0.182 | F3: =+'CONTROL PROD.TORTA'!E106 -> 0.898 | G3: =+'CONTROL PROD.TORTA'!F106 -> 0.43 | H3: =+'CONTROL PROD.TORTA'!G106 -> 0.927 | I3: =+'CONTROL PROD.TORTA'!H106 -> 0.46 | J3: =+'CONTROL PROD.TORTA'!I106 -> 25 | ... R3: =+'CONTROL PROD.TORTA'!Q106 -> 1.5492958 | S3: =+C3/$S$1*100 -> 85.628743 | T3: =+D3/1151.7 -> 0.80142398 | U3: =MEDIAN(F3:F26) -> 0.232 | V3: =+U3+U3*0.075 -> 0.2494 | W3: =+U3-U3*0.075 -> 0.2146 | X3: =MEDIAN(H2:H26) -> 0.258 | Y3: =+X3+X3*0.075 -> 0.27735 | Z3: =+X3-X3*0.075 -> 0.23865 | AA3: 0.2 | AB3: 15 | AC3: 1.8 | AI3: Tratamiento (TMH) | AJ3: =SUM(C3:C10) -> 11253 | AK3: =SUM(C11:C18) -> 11492 | AL3: =SUM(C19:C26) -> 11560 | AM3: =SUM(AJ3:AL3) -> 34305
B4: 0.41666667 | C4: =+'CONTROL PROD.TORTA'!B107 -> 1406 | D4: =+'CONTROL PROD.TORTA'!C107 -> 573 | E4: =+'CONTROL PROD.TORTA'!D107 -> 0 | F4: =+'CONTROL PROD.TORTA'!E107 -> 0 | G4: =+'CONTROL PROD.TORTA'!F107 -> 0 | H4: =+'CONTROL PROD.TORTA'!G107 -> 0 | I4: =+'CONTROL PROD.TORTA'!H107 -> 0 | J4: =+'CONTROL PROD.TORTA'!I107 -> 0 | ... R4: =+'CONTROL PROD.TORTA'!Q107 -> 2.4537522 | S4: =+C4/$S$1*100 -> 84.191617 | T4: =+D4/1151.7 -> 0.4975254 | U4: =+U3 -> 0.232 | V4: =+U4+U4*0.075 -> 0.2494 | W4: =+U4-U4*0.075 -> 0.2146 | X4: =+X3 -> 0.258 | Y4: =+X4+X4*0.075 -> 0.27735 | Z4: =+X4-X4*0.075 -> 0.23865 | AA4: 0.2 | AB4: 15 | AC4: 1.8 | AI4: Concentrado (TMS) | AJ4: =SUM(D3:D10) -> 7279 | AK4: =SUM(D11:D18) -> 7742 | AL4: =SUM(D19:D26) -> 7443 | AM4: =SUM(AJ4:AL4) -> 22464
B5: 0.45833333 | C5: =+'CONTROL PROD.TORTA'!B108 -> 1411 | D5: =+'CONTROL PROD.TORTA'!C108 -> 1115 | E5: =+'CONTROL PROD.TORTA'!D108 -> 0.189 | F5: =+'CONTROL PROD.TORTA'!E108 -> 0.737 | G5: =+'CONTROL PROD.TORTA'!F108 -> 0.41 | H5: =+'CONTROL PROD.TORTA'!G108 -> 0.668 | I5: =+'CONTROL PROD.TORTA'!H108 -> 0.4 | J5: =+'CONTROL PROD.TORTA'!I108 -> 30.1 | ... R5: =+'CONTROL PROD.TORTA'!Q108 -> 1.2654709 | S5: =+C5/$S$1*100 -> 84.491018 | T5: =+D5/1151.7 -> 0.96813406 | U5: =+U4 -> 0.232 | V5: =+U5+U5*0.075 -> 0.2494 | W5: =+U5-U5*0.075 -> 0.2146 | X5: =+X4 -> 0.258 | Y5: =+X5+X5*0.075 -> 0.27735 | Z5: =+X5-X5*0.075 -> 0.23865 | AA5: 0.2 | AB5: 15 | AC5: 1.8 | AI5: Ratio | AJ5: =+AJ3/AJ4 -> 1.5459541 | AK5: =+AK3/AK4 -> 1.484371 | AL5: =+AL3/AL4 -> 1.5531372 | AM5: =+AM3/AM4 -> 1.52711
B6: 0.5 | C6: =+'CONTROL PROD.TORTA'!B109 -> 1419 | D6: =+'CONTROL PROD.TORTA'!C109 -> 1013 | E6: =+'CONTROL PROD.TORTA'!D109 -> 0 | F6: =+'CONTROL PROD.TORTA'!E109 -> 0 | G6: =+'CONTROL PROD.TORTA'!F109 -> 0 | H6: =+'CONTROL PROD.TORTA'!G109 -> 0 | I6: =+'CONTROL PROD.TORTA'!H109 -> 0 | J6: =+'CONTROL PROD.TORTA'!I109 -> 0 | ... R6: =+'CONTROL PROD.TORTA'!Q109 -> 1.4007897 | S6: =+C6/$S$1*100 -> 84.97006 | T6: =+D6/1151.7 -> 0.87956933 | U6: =+U5 -> 0.232 | V6: =+U6+U6*0.075 -> 0.2494 | W6: =+U6-U6*0.075 -> 0.2146 | X6: =+X5 -> 0.258 | Y6: =+X6+X6*0.075 -> 0.27735 | Z6: =+X6-X6*0.075 -> 0.23865 | AA6: 0.2 | AB6: 15 | AC6: 1.8 | AI6: Recuperación (%) | AJ6: =+AJ4/AJ3 -> 0.64684973 | AK6: =+AK4/AK3 -> 0.67368604 | AL6: =+AL4/AL3 -> 0.64385813 | AM6: =+AM4/AM3 -> 0.65483166
B7: 0.54166667 | C7: =+'CONTROL PROD.TORTA'!B110 -> 1404 | D7: =+'CONTROL PROD.TORTA'!C110 -> 1012 | E7: =+'CONTROL PROD.TORTA'!D110 -> 0.178 | F7: =+'CONTROL PROD.TORTA'!E110 -> 0.694 | G7: =+'CONTROL PROD.TORTA'!F110 -> 0.4 | H7: =+'CONTROL PROD.TORTA'!G110 -> 0.76 | I7: =+'CONTROL PROD.TORTA'!H110 -> 0.43 | J7: =+'CONTROL PROD.TORTA'!I110 -> 31.2 | ... R7: =+'CONTROL PROD.TORTA'!Q110 -> 1.3873518 | S7: =+C7/$S$1*100 -> 84.071856 | T7: =+D7/1151.7 -> 0.87870105 | U7: =+U6 -> 0.232 | V7: =+U7+U7*0.075 -> 0.2494 | W7: =+U7-U7*0.075 -> 0.2146 | X7: =+X6 -> 0.258 | Y7: =+X7+X7*0.075 -> 0.27735 | Z7: =+X7-X7*0.075 -> 0.23865 | AA7: 0.2 | AB7: 15 | AC7: 1.8 | AJ7: =+AJ3/$AI$2*100 -> 84.229042 | AK7: =+AK3/$AI$2*100 -> 86.017964 | AL7: =+AL3/$AI$2*100 -> 86.526946
B8: 0.58333333 | C8: =+'CONTROL PROD.TORTA'!B111 -> 1388 | D8: =+'CONTROL PROD.TORTA'!C111 -> 1036 | E8: =+'CONTROL PROD.TORTA'!D111 -> 0 | F8: =+'CONTROL PROD.TORTA'!E111 -> 0 | G8: =+'CONTROL PROD.TORTA'!F111 -> 0 | H8: =+'CONTROL PROD.TORTA'!G111 -> 0 | I8: =+'CONTROL PROD.TORTA'!H111 -> 0 | J8: =+'CONTROL PROD.TORTA'!I111 -> 0 | ... R8: =+'CONTROL PROD.TORTA'!Q111 -> 1.3397683 | S8: =+C8/$S$1*100 -> 83.113772 | T8: =+D8/1151.7 -> 0.89953981 | U8: =+U7 -> 0.232 | V8: =+U8+U8*0.075 -> 0.2494 | W8: =+U8-U8*0.075 -> 0.2146 | X8: =+X7 -> 0.258 | Y8: =+X8+X8*0.075 -> 0.27735 | Z8: =+X8-X8*0.075 -> 0.23865 | AA8: 0.2 | AB8: 15 | AC8: 1.8
B9: 0.625 | C9: =+'CONTROL PROD.TORTA'!B112 -> 1391 | D9: =+'CONTROL PROD.TORTA'!C112 -> 1004 | E9: =+'CONTROL PROD.TORTA'!D112 -> 0.148 | F9: =+'CONTROL PROD.TORTA'!E112 -> 0.629 | G9: =+'CONTROL PROD.TORTA'!F112 -> 0.38 | H9: =+'CONTROL PROD.TORTA'!G112 -> 0.797 | I9: =+'CONTROL PROD.TORTA'!H112 -> 0.44 | J9: =+'CONTROL PROD.TORTA'!I112 -> 27 | ... R9: =+'CONTROL PROD.TORTA'!Q112 -> 1.3854582 | S9: =+C9/$S$1*100 -> 83.293413 | T9: =+D9/1151.7 -> 0.8717548 | U9: =+U8 -> 0.232 | V9: =+U9+U9*0.075 -> 0.2494 | W9: =+U9-U9*0.075 -> 0.2146 | X9: =+X8 -> 0.258 | Y9: =+X9+X9*0.075 -> 0.27735 | Z9: =+X9-X9*0.075 -> 0.23865 | AA9: 0.2 | AB9: 15 | AC9: 1.8 | AI9: Datos metalúrgicos
B10: 0.66666667 | C10: =+'CONTROL PROD.TORTA'!B113 -> 1404 | D10: =+'CONTROL PROD.TORTA'!C113 -> 603 | E10: =+'CONTROL PROD.TORTA'!D113 -> 0 | F10: =+'CONTROL PROD.TORTA'!E113 -> 0 | G10: =+'CONTROL PROD.TORTA'!F113 -> 0 | H10: =+'CONTROL PROD.TORTA'!G113 -> 0 | I10: =+'CONTROL PROD.TORTA'!H113 -> 0 | J10: =+'CONTROL PROD.TORTA'!I113 -> 0 | ... R10: =+'CONTROL PROD.TORTA'!Q113 -> 2.3283582 | S10: =+C10/$S$1*100 -> 84.071856 | T10: =+D10/1151.7 -> 0.52357385 | U10: =+U9 -> 0.232 | V10: =+U10+U10*0.075 -> 0.2494 | W10: =+U10-U10*0.075 -> 0.2146 | X10: =+X9 -> 0.258 | Y10: =+X10+X10*0.075 -> 0.27735 | Z10: =+X10-X10*0.075 -> 0.23865 | AA10: 0.2 | AB10: 15 | AC10: 1.8 | AI10: S (%) | AM10: z
B11: 0.70833333 | C11: =+'CONTROL PROD.TORTA'!B114 -> 1420 | D11: =+'CONTROL PROD.TORTA'!C114 -> 1047 | E11: =+'CONTROL PROD.TORTA'!D114 -> 0.162 | F11: =+'CONTROL PROD.TORTA'!E114 -> 0.743 | G11: =+'CONTROL PROD.TORTA'!F114 -> 0.41 | H11: =+'CONTROL PROD.TORTA'!G114 -> 0.61 | I11: =+'CONTROL PROD.TORTA'!H114 -> 0.37 | J11: =+'CONTROL PROD.TORTA'!I114 -> 27.5 | ... R11: =+'CONTROL PROD.TORTA'!Q114 -> 1.356256 | S11: =+C11/$S$1*100 -> 85.02994 | T11: =+D11/1151.7 -> 0.90909091 | U11: =+U10 -> 0.232 | V11: =+U11+U11*0.075 -> 0.2494 | W11: =+U11-U11*0.075 -> 0.2146 | X11: =+X10 -> 0.258 | Y11: =+X11+X11*0.075 -> 0.27735 | Z11: =+X11-X11*0.075 -> 0.23865 | AA11: 0.2 | AB11: 15 | AC11: 1.8 | AI11: Malla 200 (%)
B12: 0.75 | C12: =+'CONTROL PROD.TORTA'!B115 -> 1418 | D12: =+'CONTROL PROD.TORTA'!C115 -> 1018 | E12: =+'CONTROL PROD.TORTA'!D115 -> 0 | F12: =+'CONTROL PROD.TORTA'!E115 -> 0 | G12: =+'CONTROL PROD.TORTA'!F115 -> 0 | H12: =+'CONTROL PROD.TORTA'!G115 -> 0 | I12: =+'CONTROL PROD.TORTA'!H115 -> 0 | J12: =+'CONTROL PROD.TORTA'!I115 -> 0 | ... R12: =+'CONTROL PROD.TORTA'!Q115 -> 1.3929273 | S12: =+C12/$S$1*100 -> 84.91018 | T12: =+D12/1151.7 -> 0.88391074 | U12: =+U11 -> 0.232 | V12: =+U12+U12*0.075 -> 0.2494 | W12: =+U12-U12*0.075 -> 0.2146 | X12: =+X11 -> 0.258 | Y12: =+X12+X12*0.075 -> 0.27735 | Z12: =+X12-X12*0.075 -> 0.23865 | AA12: 0.2 | AB12: 15 | AC12: 1.8 | AI12: Malla 325 (%)
B13: 0.79166667 | C13: =+'CONTROL PROD.TORTA'!B116 -> 1413 | D13: =+'CONTROL PROD.TORTA'!C116 -> 912 | E13: =+'CONTROL PROD.TORTA'!D116 -> 0.161 | F13: =+'CONTROL PROD.TORTA'!E116 -> 0.757 | G13: =+'CONTROL PROD.TORTA'!F116 -> 0.43 | H13: =+'CONTROL PROD.TORTA'!G116 -> 0.661 | I13: =+'CONTROL PROD.TORTA'!H116 -> 0.39 | J13: =+'CONTROL PROD.TORTA'!I116 -> 25.3 | ... R13: =+'CONTROL PROD.TORTA'!Q116 -> 1.5493421 | S13: =+C13/$S$1*100 -> 84.610778 | T13: =+D13/1151.7 -> 0.79187288 | U13: =+U12 -> 0.232 | V13: =+U13+U13*0.075 -> 0.2494 | W13: =+U13-U13*0.075 -> 0.2146 | X13: =+X12 -> 0.258 | Y13: =+X13+X13*0.075 -> 0.27735 | Z13: =+X13-X13*0.075 -> 0.23865 | AA13: 0.2 | AB13: 15 | AC13: 1.8
B14: 0.83333333 | C14: =+'CONTROL PROD.TORTA'!B117 -> 1436 | D14: =+'CONTROL PROD.TORTA'!C117 -> 1048 | E14: =+'CONTROL PROD.TORTA'!D117 -> 0 | F14: =+'CONTROL PROD.TORTA'!E117 -> 0 | G14: =+'CONTROL PROD.TORTA'!F117 -> 0 | H14: =+'CONTROL PROD.TORTA'!G117 -> 0 | I14: =+'CONTROL PROD.TORTA'!H117 -> 0 | J14: =+'CONTROL PROD.TORTA'!I117 -> 0 | ... R14: =+'CONTROL PROD.TORTA'!Q117 -> 1.370229 | S14: =+C14/$S$1*100 -> 85.988024 | T14: =+D14/1151.7 -> 0.90995919 | U14: =+U13 -> 0.232 | V14: =+U14+U14*0.075 -> 0.2494 | W14: =+U14-U14*0.075 -> 0.2146 | X14: =+X13 -> 0.258 | Y14: =+X14+X14*0.075 -> 0.27735 | Z14: =+X14-X14*0.075 -> 0.23865 | AA14: 0.2 | AB14: 15 | AC14: 1.8 | AI14: Embarque
B15: 0.875 | C15: =+'CONTROL PROD.TORTA'!B118 -> 1440 | D15: =+'CONTROL PROD.TORTA'!C118 -> 932 | E15: =+'CONTROL PROD.TORTA'!D118 -> 0.153 | F15: =+'CONTROL PROD.TORTA'!E118 -> 0.601 | G15: =+'CONTROL PROD.TORTA'!F118 -> 0.37 | H15: =+'CONTROL PROD.TORTA'!G118 -> 0.672 | I15: =+'CONTROL PROD.TORTA'!H118 -> 0.4 | J15: =+'CONTROL PROD.TORTA'!I118 -> 24.2 | ... R15: =+'CONTROL PROD.TORTA'!Q118 -> 1.5450644 | S15: =+C15/$S$1*100 -> 86.227545 | T15: =+D15/1151.7 -> 0.80923852 | U15: =+U14 -> 0.232 | V15: =+U15+U15*0.075 -> 0.2494 | W15: =+U15-U15*0.075 -> 0.2146 | X15: =+X14 -> 0.258 | Y15: =+X15+X15*0.075 -> 0.27735 | Z15: =+X15-X15*0.075 -> 0.23865 | AA15: 0.2 | AB15: 15 | AC15: 1.8 | AI15: Nave | AJ15: =+AP72 -> 0
B16: 0.91666667 | C16: =+'CONTROL PROD.TORTA'!B119 -> 1443 | D16: =+'CONTROL PROD.TORTA'!C119 -> 898 | E16: =+'CONTROL PROD.TORTA'!D119 -> 0 | F16: =+'CONTROL PROD.TORTA'!E119 -> 0 | G16: =+'CONTROL PROD.TORTA'!F119 -> 0 | H16: =+'CONTROL PROD.TORTA'!G119 -> 0 | I16: =+'CONTROL PROD.TORTA'!H119 -> 0 | J16: =+'CONTROL PROD.TORTA'!I119 -> 0 | ... R16: =+'CONTROL PROD.TORTA'!Q119 -> 1.6069042 | S16: =+C16/$S$1*100 -> 86.407186 | T16: =+D16/1151.7 -> 0.77971694 | U16: =+U15 -> 0.232 | V16: =+U16+U16*0.075 -> 0.2494 | W16: =+U16-U16*0.075 -> 0.2146 | X16: =+X15 -> 0.258 | Y16: =+X16+X16*0.075 -> 0.27735 | Z16: =+X16-X16*0.075 -> 0.23865 | AA16: 0.2 | AB16: 15 | AC16: 1.8 | AI16: Fecha de inicio | AJ16: =+AQ72 -> 0
B17: 0.95833333 | C17: =+'CONTROL PROD.TORTA'!B120 -> 1462 | D17: =+'CONTROL PROD.TORTA'!C120 -> 967 | E17: =+'CONTROL PROD.TORTA'!D120 -> 0.14 | F17: =+'CONTROL PROD.TORTA'!E120 -> 0.636 | G17: =+'CONTROL PROD.TORTA'!F120 -> 0.39 | H17: =+'CONTROL PROD.TORTA'!G120 -> 0.703 | I17: =+'CONTROL PROD.TORTA'!H120 -> 0.42 | J17: =+'CONTROL PROD.TORTA'!I120 -> 23.7 | ... R17: =+'CONTROL PROD.TORTA'!Q120 -> 1.5118925 | S17: =+C17/$S$1*100 -> 87.54491 | T17: =+D17/1151.7 -> 0.83962838 | U17: =+U16 -> 0.232 | V17: =+U17+U17*0.075 -> 0.2494 | W17: =+U17-U17*0.075 -> 0.2146 | X17: =+X16 -> 0.258 | Y17: =+X17+X17*0.075 -> 0.27735 | Z17: =+X17-X17*0.075 -> 0.23865 | AA17: 0.2 | AB17: 15 | AC17: 1.8 | AI17: Fecha de término
B18: 1 | C18: =+'CONTROL PROD.TORTA'!B121 -> 1460 | D18: =+'CONTROL PROD.TORTA'!C121 -> 920 | E18: =+'CONTROL PROD.TORTA'!D121 -> 0 | F18: =+'CONTROL PROD.TORTA'!E121 -> 0 | G18: =+'CONTROL PROD.TORTA'!F121 -> 0 | H18: =+'CONTROL PROD.TORTA'!G121 -> 0 | I18: =+'CONTROL PROD.TORTA'!H121 -> 0 | J18: =+'CONTROL PROD.TORTA'!I121 -> 0 | ... R18: =+'CONTROL PROD.TORTA'!Q121 -> 1.5869565 | S18: =+C18/$S$1*100 -> 87.42515 | T18: =+D18/1151.7 -> 0.79881914 | U18: =+U17 -> 0.232 | V18: =+U18+U18*0.075 -> 0.2494 | W18: =+U18-U18*0.075 -> 0.2146 | X18: =+X17 -> 0.258 | Y18: =+X18+X18*0.075 -> 0.27735 | Z18: =+X18-X18*0.075 -> 0.23865 | AA18: 0.2 | AB18: 15 | AC18: 1.8 | AI18: Embarcado (TMH) | AJ18: =+AS72 -> 0
B19: 1.0416667 | C19: =+'CONTROL PROD.TORTA'!B122 -> 1455 | D19: =+'CONTROL PROD.TORTA'!C122 -> 960 | E19: =+'CONTROL PROD.TORTA'!D122 -> 0.136 | F19: =+'CONTROL PROD.TORTA'!E122 -> 0.464 | G19: =+'CONTROL PROD.TORTA'!F122 -> 0.25 | H19: =+'CONTROL PROD.TORTA'!G122 -> 0.527 | I19: =+'CONTROL PROD.TORTA'!H122 -> 0.28 | J19: =+'CONTROL PROD.TORTA'!I122 -> 28.2 | ... R19: =+'CONTROL PROD.TORTA'!Q122 -> 1.515625 | S19: =+C19/$S$1*100 -> 87.125749 | T19: =+D19/1151.7 -> 0.8335504 | U19: =+U18 -> 0.232 | V19: =+U19+U19*0.075 -> 0.2494 | W19: =+U19-U19*0.075 -> 0.2146 | X19: =+X18 -> 0.258 | Y19: =+X19+X19*0.075 -> 0.27735 | Z19: =+X19-X19*0.075 -> 0.23865 | AA19: 0.2 | AB19: 15 | AC19: 1.8
B20: 1.0833333 | C20: =+'CONTROL PROD.TORTA'!B123 -> 1438 | D20: =+'CONTROL PROD.TORTA'!C123 -> 902 | E20: =+'CONTROL PROD.TORTA'!D123 -> 0 | F20: =+'CONTROL PROD.TORTA'!E123 -> 0 | G20: =+'CONTROL PROD.TORTA'!F123 -> 0 | H20: =+'CONTROL PROD.TORTA'!G123 -> 0 | I20: =+'CONTROL PROD.TORTA'!H123 -> 0 | J20: =+'CONTROL PROD.TORTA'!I123 -> 0 | ... R20: =+'CONTROL PROD.TORTA'!Q123 -> 1.594235 | S20: =+C20/$S$1*100 -> 86.107784 | T20: =+D20/1151.7 -> 0.78319007 | U20: =+U19 -> 0.232 | V20: =+U20+U20*0.075 -> 0.2494 | W20: =+U20-U20*0.075 -> 0.2146 | X20: =+X19 -> 0.258 | Y20: =+X20+X20*0.075 -> 0.27735 | Z20: =+X20-X20*0.075 -> 0.23865 | AA20: 0.2 | AB20: 15 | AC20: 1.8 | AI20: Concentrado
B21: 1.125 | C21: =+'CONTROL PROD.TORTA'!B124 -> 1447 | D21: =+'CONTROL PROD.TORTA'!C124 -> 1000 | E21: =+'CONTROL PROD.TORTA'!D124 -> 0.132 | F21: =+'CONTROL PROD.TORTA'!E124 -> 0.474 | G21: =+'CONTROL PROD.TORTA'!F124 -> 0.3 | H21: =+'CONTROL PROD.TORTA'!G124 -> 0.516 | I21: =+'CONTROL PROD.TORTA'!H124 -> 0.25 | J21: =+'CONTROL PROD.TORTA'!I124 -> 25.1 | ... R21: =+'CONTROL PROD.TORTA'!Q124 -> 1.447 | S21: =+C21/$S$1*100 -> 86.646707 | T21: =+D21/1151.7 -> 0.86828167 | U21: =+U20 -> 0.232 | V21: =+U21+U21*0.075 -> 0.2494 | W21: =+U21-U21*0.075 -> 0.2146 | X21: =+X20 -> 0.258 | Y21: =+X21+X21*0.075 -> 0.27735 | Z21: =+X21-X21*0.075 -> 0.23865 | AA21: 0.2 | AB21: 15 | AC21: 1.8 | AJ21: Diario | AK21: Semana | AL21: Agosto | AM21: Anual
B22: 1.1666667 | C22: =+'CONTROL PROD.TORTA'!B125 -> 1418 | D22: =+'CONTROL PROD.TORTA'!C125 -> 824 | E22: =+'CONTROL PROD.TORTA'!D125 -> 0 | F22: =+'CONTROL PROD.TORTA'!E125 -> 0 | G22: =+'CONTROL PROD.TORTA'!F125 -> 0 | H22: =+'CONTROL PROD.TORTA'!G125 -> 0 | I22: =+'CONTROL PROD.TORTA'!H125 -> 0 | J22: =+'CONTROL PROD.TORTA'!I125 -> 0 | ... R22: =+'CONTROL PROD.TORTA'!Q125 -> 1.7208738 | S22: =+C22/$S$1*100 -> 84.91018 | T22: =+D22/1151.7 -> 0.7154641 | U22: =+U21 -> 0.232 | V22: =+U22+U22*0.075 -> 0.2494 | W22: =+U22-U22*0.075 -> 0.2146 | X22: =+X21 -> 0.258 | Y22: =+X22+X22*0.075 -> 0.27735 | Z22: =+X22-X22*0.075 -> 0.23865 | AA22: 0.2 | AB22: 15 | AC22: 1.8 | AI22: Acumulado (TMS) | AJ22: =+AJ89 -> 18772 | AK22: =+AL89 -> 141713 | AL22: =+AJ95 -> 542272 | AM22: =+AK113 -> 5669033 | AN22: =+AL113 -> -252669.12
B23: 1.2083333 | C23: =+'CONTROL PROD.TORTA'!B126 -> 1454 | D23: =+'CONTROL PROD.TORTA'!C126 -> 812 | E23: =+'CONTROL PROD.TORTA'!D126 -> 0.155 | F23: =+'CONTROL PROD.TORTA'!E126 -> 0.528 | G23: =+'CONTROL PROD.TORTA'!F126 -> 0.32 | H23: =+'CONTROL PROD.TORTA'!G126 -> 0.57 | I23: =+'CONTROL PROD.TORTA'!H126 -> 0.36 | J23: =+'CONTROL PROD.TORTA'!I126 -> 30 | ... R23: =+'CONTROL PROD.TORTA'!Q126 -> 1.7906404 | S23: =+C23/$S$1*100 -> 87.065868 | T23: =+D23/1151.7 -> 0.70504472 | U23: =+U22 -> 0.232 | V23: =+U23+U23*0.075 -> 0.2494 | W23: =+U23-U23*0.075 -> 0.2146 | X23: =+X22 -> 0.258 | Y23: =+X23+X23*0.075 -> 0.27735 | Z23: =+X23-X23*0.075 -> 0.23865 | AA23: 0.2 | AB23: 15 | AC23: 1.8 | AI23: Ppto 2026 (TMS) | AJ23: =+AL63 -> 23201.567 | AK23: 162410 | AL23: =+AJ106 -> 660185 | AM23: 8000015
B24: 1.25 | C24: =+'CONTROL PROD.TORTA'!B127 -> 1445 | D24: =+'CONTROL PROD.TORTA'!C127 -> 1046 | E24: =+'CONTROL PROD.TORTA'!D127 -> 0 | F24: =+'CONTROL PROD.TORTA'!E127 -> 0 | G24: =+'CONTROL PROD.TORTA'!F127 -> 0 | H24: =+'CONTROL PROD.TORTA'!G127 -> 0 | I24: =+'CONTROL PROD.TORTA'!H127 -> 0 | J24: =+'CONTROL PROD.TORTA'!I127 -> 0 | ... R24: =+'CONTROL PROD.TORTA'!Q127 -> 1.3814532 | S24: =+C24/$S$1*100 -> 86.526946 | T24: =+D24/1151.7 -> 0.90822263 | U24: =+U23 -> 0.232 | V24: =+U24+U24*0.075 -> 0.2494 | W24: =+U24-U24*0.075 -> 0.2146 | X24: =+X23 -> 0.258 | Y24: =+X24+X24*0.075 -> 0.27735 | Z24: =+X24-X24*0.075 -> 0.23865 | AA24: 0.2 | AB24: 15 | AC24: 1.8 | AI24: % cumplimiento | AJ24: =+AJ22/AJ23 -> 0.80908329 | AK24: =+AK22/AK23 -> 0.87256327 | AL24: =+AL22/AL23 -> 0.821394 | AM24: =+AM22/AM23 -> 0.7086278
B25: 1.2916667 | C25: =+'CONTROL PROD.TORTA'!B128 -> 1457 | D25: =+'CONTROL PROD.TORTA'!C128 -> 1066 | E25: =+'CONTROL PROD.TORTA'!D128 -> 0.162 | F25: =+'CONTROL PROD.TORTA'!E128 -> 0.49 | G25: =+'CONTROL PROD.TORTA'!F128 -> 0.31 | H25: =+'CONTROL PROD.TORTA'!G128 -> 0.527 | I25: =+'CONTROL PROD.TORTA'!H128 -> 0.34 | J25: =+'CONTROL PROD.TORTA'!I128 -> 25.4 | ... R25: =+'CONTROL PROD.TORTA'!Q128 -> 1.3667917 | S25: =+C25/$S$1*100 -> 87.245509 | T25: =+D25/1151.7 -> 0.92558826 | U25: =+U24 -> 0.232 | V25: =+U25+U25*0.075 -> 0.2494 | W25: =+U25-U25*0.075 -> 0.2146 | X25: =+X24 -> 0.258 | Y25: =+X25+X25*0.075 -> 0.27735 | Z25: =+X25-X25*0.075 -> 0.23865 | AA25: 0.2 | AB25: 15 | AC25: 1.8
B26: 1.3333333 | C26: =+'CONTROL PROD.TORTA'!B129 -> 1446 | D26: =+'CONTROL PROD.TORTA'!C129 -> 833 | E26: =+'CONTROL PROD.TORTA'!D129 -> 0 | F26: =+'CONTROL PROD.TORTA'!E129 -> 0 | G26: =+'CONTROL PROD.TORTA'!F129 -> 0 | H26: =+'CONTROL PROD.TORTA'!G129 -> 0 | I26: =+'CONTROL PROD.TORTA'!H129 -> 0 | J26: =+'CONTROL PROD.TORTA'!I129 -> 0 | ... R26: =+'CONTROL PROD.TORTA'!Q129 -> 1.7358944 | S26: =+C26/$S$1*100 -> 86.586826 | T26: =+D26/1151.7 -> 0.72327863 | U26: =+U25 -> 0.232 | V26: =+U26+U26*0.075 -> 0.2494 | W26: =+U26-U26*0.075 -> 0.2146 | X26: =+X25 -> 0.258 | Y26: =+X26+X26*0.075 -> 0.27735 | Z26: =+X26-X26*0.075 -> 0.23865 | AA26: 0.2 | AB26: 15 | AC26: 1.8 | AI26: Sinter Calibrado
A27: Total | C27: =+'CONTROL PROD.TORTA'!B130 -> 34305 | D27: =+'CONTROL PROD.TORTA'!C130 -> 22464 | E27: =+'CONTROL PROD.TORTA'!D130 -> 0.15816667 | F27: =+'CONTROL PROD.TORTA'!E130 -> 0.63758333 | G27: =+'CONTROL PROD.TORTA'!F130 -> 0.36666667 | H27: =+'CONTROL PROD.TORTA'!G130 -> 0.6615 | I27: =+'CONTROL PROD.TORTA'!H130 -> 0.37833333 | J27: =+'CONTROL PROD.TORTA'!I130 -> 26.891667 | ... R27: =+'CONTROL PROD.TORTA'!Q130 -> 1.52711 | S27: =AVERAGE(S3:S26) -> 85.591317 | T27: =+D27/T1 -> 0.81269488 | U27: =+C27/S27*100 -> 40080 | AJ27: Diario | AK27: Semana | AL27: Agosto | AM27: Anual
AI28: Acumulado (TMS) | AJ28: =+AK89 -> 3994 | AK28: =+AM89 -> 21323 | AL28: =+AK95 -> 93041 | AM28: =+AN113 -> 1099219 | AN28: =+AO113 -> 215778.14
T29: =+C27/U27 -> 0.85591317 | AI29: Ppto 2026 (TMS) | AJ29: =+AM63 -> 3333.3333 | AK29: 23333 | AL29: 100000 | AM29: 1200000
AI30: % cumplimiento | AJ30: =+AJ28/AJ29 -> 1.1982 | AK30: =+AK28/AK29 -> 0.91385591 | AL30: =+AL28/AL29 -> 0.93041 | AM30: =+AM28/AM29 -> 0.91601583
AL55: 22218 | AM55: =+AL55*5 -> 111090
AL56: 18889.52 | AM56: =+AL56*2 -> 37779.04
AM57: =SUM(AM55:AM56) -> 148869.04
AJ61: 45361 | AK61: 6693
AI62: SETIEMBRE | AP62: SETIEMBRE
AI63: Día | AJ63: Concentrado | AK63: Sinter Calibrado | AL63: 23201.567 | AM63: 3333.3333 | AN63: 26 | AP63: Embarque
AI64: 1 | AJ64: 23744 | AK64: 3144 | AO64: Nro | AP64: Setiembre | AQ64: Inicio | AR64: Fin | AS64: Total (TM) | AT64: oxidado | AU64: sinter
AI65: 2 | AJ65: 24312 | AK65: 3286 | AO65: 1 | AP65: M/V “EPIC UNION ” | AQ65: 26/08/2026 12:15hrs | AR65: 01/09/2026 11:55 hrs | AS65: 168408
AI66: 3 | AJ66: 21281 | AK66: 3318 | AO66: 2 | AP66: M/V “ASL LOONG” | AQ66: 01/09/2026 14:15hrs | AR66: 03/09/2026 🕐 20:13 hrs | AS66: 163104.86
AI67: 4 | AJ67: 21231 | AK67: 4243 | AO67: 3 | AP67: M/V "SHANDOND HUA ZHANG” | AQ67: 04/09/2026 🕐 00:00 hrs
...

Sheet CONTROL PROD.TORTA
A3: CONTROL DIARIO DE PRODUCCION DE TORTA - ZONA ANTIGUA
A5: DIA | B5: MINERAL (TMS) | C5: TORTA (TMS) | D5: S | E5: RM 1/2/3 DTT-100 S | F5: RM 1/2/3 DTT-100 S/F | G5: RM 5/6/7/8/9 DTT-100 S | H5: RM 5/6/7/8/9 DTT-100 S/F | I5: ESP.Ant Fe | J5: ESP.N Fe Sol | K5: ESP.Ant FeO | L5: ESP.N FeO | M5: Promedio de Fe Sol | N5: Promedio de FeO | O5: H2O | P5: %RECUP. | Q5: RATIO | R5: OBS. MAGNETICA | S5: OBS. FILTROS
A6: 0.375 | B6: 1565 | C6: 1029 | D6: 0.177 | E6: 0.736 | F6: 0.44 | G6: 0.877 | H6: 0.49 | I6: 25.4 | J6: 12.3 | K6: 2 | L6: 1.6 | M6: =I6*0.4+J6*0.6 -> 17.54 | N6: =+(K6*0.4+L6*0.6) -> 1.76 | O6: 8.2 | P6: =+IFERROR(C6/B6,"") -> 0.65750799 | Q6: =IFERROR(1/P6,0) -> 1.5208941
A7: 0.41666667 | B7: 1586 | C7: 1072 | P7: =+IFERROR(C7/B7,"") -> 0.67591425 | Q7: =IFERROR(1/P7,0) -> 1.4794776
A8: 0.45833333 | B8: 1562 | C8: 938 | D8: 0.172 | E8: 0.778 | F8: 0.45 | G8: 0.871 | H8: 0.49 | I8: 25.5 | J8: 14 | K8: 2.5 | L8: 2.2 | M8: =+(I8*0.4+J8*0.6) -> 18.6 | N8: =+(K8*0.4+L8*0.6) -> 2.32 | O8: 8.6 | P8: =+IFERROR(C8/B8,"") -> 0.60051216 | Q8: =IFERROR(1/P8,0) -> 1.6652452
A9: 0.5 | B9: 1559 | C9: 1015 | P9: =+IFERROR(C9/B9,"") -> 0.65105837 | Q9: =IFERROR(1/P9,0) -> 1.5359606
A10: 0.54166667 | B10: 1570 | C10: 1003 | D10: 0.194 | E10: 0.766 | F10: 0.44 | G10: 0.738 | H10: 0.42 | I10: 29.4 | J10: 14.5 | K10: 3.2 | L10: 2.4 | M10: =+(I10*0.4+J10*0.6) -> 20.46 | N10: =+(K10*0.4+L10*0.6) -> 2.72 | O10: 8.3 | P10: =+IFERROR(C10/B10,"") -> 0.6388535 | Q10: =IFERROR(1/P10,0) -> 1.5653041
A11: 0.58333333 | B11: 1583 | C11: 1033 | P11: =+IFERROR(C11/B11,"") -> 0.65255843 | Q11: =IFERROR(1/P11,0) -> 1.5324298
A12: 0.625 | B12: 1594 | C12: 1004 | D12: 0.17 | E12: 0.703 | F12: 0.4 | G12: 0.93 | H12: 0.5 | I12: 24.2 | J12: 13.2 | K12: 1.6 | L12: 2.1 | M12: =+(I12*0.4+J12*0.6) -> 17.6 | N12: =+(K12*0.4+L12*0.6) -> 1.9 | O12: 8.4 | P12: =+IFERROR(C12/B12,"") -> 0.62986198 | Q12: =IFERROR(1/P12,0) -> 1.5876494
A13: 0.66666667 | B13: 1558 | C13: 991 | P13: =+IFERROR(C13/B13,"") -> 0.63607189 | Q13: =IFERROR(1/P13,0) -> 1.5721493
A14: 0.70833333 | B14: 1575 | C14: 1071 | D14: 0.166 | E14: 0.829 | F14: 0.46 | G14: 0.813 | H14: 0.47 | I14: 24.9 | J14: 15.1 | K14: 1.9 | L14: 2.3 | M14: =+(I14*0.4+J14*0.6) -> 19.02 | N14: =+(K14*0.4+L14*0.6) -> 2.14 | O14: 8.3 | P14: =+IFERROR(C14/B14,"") -> 0.68 | Q14: =IFERROR(1/P14,0) -> 1.4705882
A15: 0.75 | B15: 1653 | C15: 1143 | P15: =+IFERROR(C15/B15,"") -> 0.69147005 | Q15: =IFERROR(1/P15,0) -> 1.4461942
A16: 0.79166667 | B16: 1583 | C16: 903 | D16: 0.161 | E16: 0.827 | F16: 0.45 | G16: 0.865 | H16: 0.47 | I16: 31.8 | J16: 15.8 | K16: 2.4 | L16: 2.4 | M16: =+(I16*0.4+J16*0.6) -> 22.2 | N16: =+(K16*0.4+L16*0.6) -> 2.4 | O16: 8.2 | P16: =+IFERROR(C16/B16,"") -> 0.57043588 | Q16: =IFERROR(1/P16,0) -> 1.7530454
A17: 0.83333333 | B17: 1581 | C17: 1076 | P17: =+IFERROR(C17/B17,"") -> 0.68058191 | Q17: =IFERROR(1/P17,0) -> 1.4693309 | R17: Bancos KYF10 trabajando en manual
A18: 0.875 | B18: 1588 | C18: 1183 | D18: 0.179 | E18: 0.72 | F18: 0.44 | G18: 0.531 | H18: 0.36 | I18: 22.2 | J18: 15.9 | K18: 2.1 | L18: 2 | M18: =+(I18*0.4+J18*0.6) -> 18.42 | N18: =+(K18*0.4+L18*0.6) -> 2.04 | O18: 8.4 | P18: =+IFERROR(C18/B18,"") -> 0.74496222 | Q18: =IFERROR(1/P18,0) -> 1.34235 | R18: Rm01 reponen guardas del motor.. /// Se reduce dosificación de acido oxalico | S18: 21:00 a 21:20 hrs paró espesador 053-003 por alto torque, se observa lubricación deficiente en cajas de transmision, se agrega aceite operando con parametros normales
A19: 0.91666667 | B19: 1460 | C19: 1101 | P19: =+IFERROR(C19/B19,"") -> 0.75410959 | Q19: =IFERROR(1/P19,0) -> 1.3260672 | R19: Se realizó agregado de barras molinos 032-082/083/084/085
A20: 0.95833333 | B20: 1320 | C20: 1146 | D20: 0.168 | E20: 0.823 | F20: 0.46 | G20: 0.605 | H20: 0.37 | I20: 24.2 | J20: 15.6 | K20: 2.2 | L20: 2.6 | M20: =+(I20*0.4+J20*0.6) -> 19.04 | N20: =+(K20*0.4+L20*0.6) -> 2.44 | O20: 8.4 | P20: =+IFERROR(C20/B20,"") -> 0.86818182 | Q20: =IFERROR(1/P20,0) -> 1.1518325 | R20: 22:49 hrs arrancó barras 1 en reemplazo del Rm02 | S20: Personal mecánico culmina lubricación de cajas de transmisión lado norte y sur del espesador 053-003
A21: 0 | B21: 1492 | C21: 1007 | P21: =+IFERROR(C21/B21,"") -> 0.67493298 | Q21: =IFERROR(1/P21,0) -> 1.4816286 | R21: Se reduce dosificación de acido oxalico
A22: 0.041666667 | B22: 1585 | C22: 1079 | D22: 0.187 | E22: 0.963 | F22: 0.56 | G22: 0.782 | H22: 0.47 | I22: 34.3 | J22: 15.2 | K22: 3.4 | L22: 2.4 | M22: =+(I22*0.4+J22*0.6) -> 22.84 | N22: =+(K22*0.4+L22*0.6) -> 2.8 | O22: 8.1 | P22: =+IFERROR(C22/B22,"") -> 0.6807571 | Q22: =IFERROR(1/P22,0) -> 1.4689527 | R22: Se inicia agregado de conos
A23: 0.083333333 | B23: 1578 | C23: 874 | P23: =+IFERROR(C23/B23,"") -> 0.55386565 | Q23: =IFERROR(1/P23,0) -> 1.805492 | R23: 210-295A/B.- Limpieza cajón de concentrado PURGA
A24: 0.125 | B24: 1555 | C24: 811 | D24: 0.203 | E24: 0.787 | F24: 0.46 | G24: 0.705 | H24: 0.43 | I24: 32.2 | J24: 20.1 | K24: 4.4 | L24: 4.5 | M24: =+(I24*0.4+J24*0.6) -> 24.94 | N24: =+(K24*0.4+L24*0.6) -> 4.46 | O24: 8.1 | P24: =+IFERROR(C24/B24,"") -> 0.52154341 | Q24: =IFERROR(1/P24,0) -> 1.9173859 | R24: 210-296A/B.- Limpieza cajón de concentrado PURGA. // Se incrementa dosificación de xantato, se reduce colchones celdas grandes
A25: 0.16666667 | B25: 1390 | C25: 794 | P25: =+IFERROR(C25/B25,"") -> 0.57122302 | Q25: =IFERROR(1/P25,0) -> 1.7506297 | R25: Agregado de barras molinos 032-086/088/089
A26: 0.20833333 | B26: 1525 | C26: 1045 | D26: 0.2 | E26: 0.841 | F26: 0.47 | G26: 0.915 | H26: 0.52 | I26: 29.3 | J26: 19.2 | K26: 2.9 | L26: 3.5 | M26: =+(I26*0.4+J26*0.6) -> 23.24 | N26: =+(K26*0.4+L26*0.6) -> 3.26 | O26: 8 | P26: =+IFERROR(C26/B26,"") -> 0.6852459 | Q26: =IFERROR(1/P26,0) -> 1.4593301
A27: 0.25 | B27: 1548 | C27: 994 | P27: =+IFERROR(C27/B27,"") -> 0.64211886 | Q27: =IFERROR(1/P27,0) -> 1.5573441 | R27: Se continua agregado de conos
A28: 0.29166667 | B28: 1551 | C28: 936 | D28: 0.203 | E28: 0.781 | F28: 0.44 | G28: 0.846 | H28: 0.47 | I28: 26.5 | J28: 18.2 | K28: 2.6 | L28: 2.8 | M28: =+(I28*0.4+J28*0.6) -> 21.52 | N28: =+(K28*0.4+L28*0.6) -> 2.72 | O28: 8.4 | P28: =+IFERROR(C28/B28,"") -> 0.60348162 | Q28: =IFERROR(1/P28,0) -> 1.6570513
A29: 0.33333333 | B29: 1588 | C29: 996 | P29: =+IFERROR(C29/B29,"") -> 0.62720403 | Q29: =IFERROR(1/P29,0) -> 1.5943775
A30: 46266 | B30: =+IF(SUM(B6:B29)=0, "", SUM(B6:B29)) -> 37149 | C30: =+IF(SUM(C6:C29)=0, "", SUM(C6:C29)) -> 24244 | D30: =+IFERROR((AVERAGE(D6:D29)),0) -> 0.18166667 | E30: =+IFERROR((AVERAGE(E6:E29)),0) -> 0.79616667 | F30: =+IFERROR((AVERAGE(F6:F29)),0) -> 0.45583333 | G30: =+IFERROR((AVERAGE(G6:G29)),0) -> 0.78983333 | H30: =+IFERROR((AVERAGE(H6:H29)),0) -> 0.455 | I30: =+IFERROR((AVERAGE(I6:I29)),"") -> 27.491667 | J30: =+IFERROR((AVERAGE(J6:J29)),"") -> 15.758333 | K30: =+IFERROR((AVERAGE(K6:K29)),"") -> 2.6 | L30: =+IFERROR((AVERAGE(L6:L29)),"") -> 2.5666667 | M30: =+IFERROR((AVERAGE(M6:M29)),0) -> 20.451667 | N30: =+IFERROR((AVERAGE(N6:N29)),0) -> 2.58 | O30: =+IFERROR((AVERAGE(O6:O29)),0) -> 8.2833333 | P30: =+IFERROR(C30/B30,"") -> 0.65261514 | Q30: =IFERROR(1/P30,0) -> 1.5322967
A31: 0.375 | B31: 1631 | C31: 1143 | D31: 0.199 | E31: 0.991 | F31: 0.53 | G31: 0.818 | H31: 0.46 | I31: 29.6 | J31: 13.4 | K31: 2.6 | L31: 1.7 | M31: =(I31*0.4+J31*0.6) -> 19.88 | N31: =(K31*0.4+L31*0.6) -> 2.06 | O31: 8.4 | P31: =+IFERROR(C31/B31,"") -> 0.70079706 | Q31: =IFERROR(1/P31,0) -> 1.4269466
A32: 0.41666667 | B32: 1603 | C32: 1084 | P32: =+IFERROR(C32/B32,"") -> 0.67623206 | Q32: =IFERROR(1/P32,0) -> 1.4787823
A33: 0.45833333 | B33: 1615 | C33: 922 | D33: 0.191 | E33: 0.787 | F33: 0.44 | G33: 0.73 | H33: 0.43 | I33: 29.3 | J33: 15.9 | K33: 2.7 | L33: 2.5 | M33: =(I33*0.4+J33*0.6) -> 21.26 | N33: =(K33*0.4+L33*0.6) -> 2.58 | O33: 8.4 | P33: =+IFERROR(C33/B33,"") -> 0.57089783 | Q33: =IFERROR(1/P33,0) -> 1.7516269
A34: 0.5 | B34: 1608 | C34: 1044 | P34: =+IFERROR(C34/B34,"") -> 0.64925373 | Q34: =IFERROR(1/P34,0) -> 1.5402299
A35: 0.54166667 | B35: 1612 | C35: 1030 | D35: 0.202 | E35: 0.73 | F35: 0.46 | G35: 0.565 | H35: 0.39 | I35: 29.8 | J35: 15.5 | K35: 2.9 | L35: 2.3 | M35: =(I35*0.4+J35*0.6) -> 21.22 | N35: =(K35*0.4+L35*0.6) -> 2.54 | O35: 8.1 | P35: =+IFERROR(C35/B35,"") -> 0.63895782 | Q35: =IFERROR(1/P35,0) -> 1.5650485
A36: 0.58333333 | B36: 1606 | C36: 1083 | P36: =+IFERROR(C36/B36,"") -> 0.6743462 | Q36: =IFERROR(1/P36,0) -> 1.4829178
A37: 0.625 | B37: 1562 | C37: 1090 | D37: 0.219 | E37: 0.669 | F37: 0.4 | G37: 0.575 | H37: 0.41 | I37: 29.6 | J37: 16.8 | K37: 2.8 | L37: 2.5 | M37: =(I37*0.4+J37*0.6) -> 21.92 | N37: =(K37*0.4+L37*0.6) -> 2.62 | O37: 8.2 | P37: =+IFERROR(C37/B37,"") -> 0.6978233 | Q37: =IFERROR(1/P37,0) -> 1.4330275
A38: 0.66666667 | B38: 1550 | C38: 1081 | P38: =+IFERROR(C38/B38,"") -> 0.69741935 | Q38: =IFERROR(1/P38,0) -> 1.4338575
A39: 0.70833333 | B39: 1610 | C39: 1104 | D39: 0.18 | E39: 0.689 | F39: 0.41 | G39: 0.7 | H39: 0.43 | I39: 26.1 | J39: 14.3 | K39: 2.1 | L39: 1.6 | M39: =(I39*0.4+J39*0.6) -> 19.02 | N39: =(K39*0.4+L39*0.6) -> 1.8 | O39: 8.3 | P39: =+IFERROR(C39/B39,"") -> 0.68571429 | Q39: =IFERROR(1/P39,0) -> 1.4583333
A40: 0.75 | B40: 1605 | C40: 1055 | P40: =+IFERROR(C40/B40,"") -> 0.65732087 | Q40: =IFERROR(1/P40,0) -> 1.521327
A41: 0.79166667 | B41: 1597 | C41: 1067 | D41: 0.2 | E41: 0.773 | F41: 0.44 | G41: 0.605 | H41: 0.4 | I41: 27.9 | J41: 18.1 | K41: 2.4 | L41: 2 | M41: =(I41*0.4+J41*0.6) -> 22.02 | N41: =(K41*0.4+L41*0.6) -> 2.16 | O41: 8.6 | P41: =+IFERROR(C41/B41,"") -> 0.66812774 | Q41: =IFERROR(1/P41,0) -> 1.4967198
A42: 0.83333333 | B42: 1587 | C42: 977 | P42: =+IFERROR(C42/B42,"") -> 0.61562697 | Q42: =IFERROR(1/P42,0) -> 1.6243603
A43: 0.875 | B43: 1590 | C43: 1067 | D43: 0.201 | E43: 0.812 | F43: 0.47 | G43: 0.609 | H43: 0.43 | I43: 22.4 | J43: 15.1 | K43: 1.8 | L43: 2.1 | M43: =(I43*0.4+J43*0.6) -> 18.02 | N43: =(K43*0.4+L43*0.6) -> 1.98 | O43: 8.1 | P43: =+IFERROR(C43/B43,"") -> 0.67106918 | Q43: =IFERROR(1/P43,0) -> 1.4901593
...

Sheet Fallas
A2: Fecha | B2: Equipo | C2: Inicio de parada | D2: Arranque | E2: Tiempo perdido (hrs) | F2: MIneral no procesado (TM) | G2: Concentrado no producido (TMS) | H2: Falla (mecánica/eléctrica /instrumentación/operaciones) | I2: Motivo
A3: 46266 | B3: 032-081 | C3: 0 | D3: 0.95069444 | E3: 0 | F3: =+E3*200 -> 0 | G3: =+F3/1.5 -> 0 | H3: Operaciones | I3: Arranco en reemplazo Rm02
B4: 032-082 | C4: 0.95347222 | D4: 0 | E4: 0 | F4: =+E4*200 -> 0 | G4: =+F4/1.5 -> 0 | H4: Operaciones | I4: Paró por ajuste de pernos. Stand by
A5: 46268 | B5: 032-089 | C5: 0.72222222 | D5: 0.80138889 | E5: 1.9 | F5: =220*E5 -> 418 | G5: =+F5/1.5 -> 278.66667 | H5: Falla mecanica | I5: Por parada del bolas 9
B6: 032-089 | C6: 0.81111111 | D6: 0.91875 | E6: 2.58 | F6: =220*E6 -> 567.6 | G6: =+F6/1.5 -> 378.4 | H6: Falla electrica | I6: Por parada del bolas 9
B7: 032-209 | C7: 0.72708333 | D7: 0.80069444 | E7: 1.9 | F7: =180*E7 -> 342 | G7: =+F7/1.5 -> 228 | H7: Falla mecanica | I7: Perforacion en distribuidor de ciclones
B8: 032-209 | C8: 0.81041667 | D8: 0.91666667 | E8: 2.5 | F8: =180*E8 -> 450 | G8: =+F8/1.5 -> 300 | H8: Falla electrica | I8: Falla excitación del motor
A9: 46238 | B9: 032-082 | C9: 0 | D9: 0.70625 | E9: 0 | F9: =220*E9 -> 0 | G9: =+F9/1.5 -> 0 | H9: Operaciones | I9: Arranco en reemplazo Rm04
B10: 032-084 | C10: 0.70138889 | D10: 0 | E10: 0 | F10: =220*E10 -> 0 | G10: =+F10/1.5 -> 0 | H10: Operaciones | I10: Paró por limpieza trunnion alimentación. Stand by
B11: 032-085 | C11: 0 | D11: 0.77708333 | E11: 0 | F11: =220*E11 -> 0 | G11: =+F11/1.5 -> 0 | H11: Operaciones | I11: Arranco en reemplazo Rm07
B12: 032-087 | C12: 0.76041667 | D12: 0 | E12: 0 | F12: =220*E12 -> 0 | G12: =+F12/1.5 -> 0 | H12: Operaciones | I12: Paró por arranque Rm05. Stand by
B13: 032-089 | C13: 0.63888889 | D13: 0.67777778 | E13: 0.95 | F13: =220*E13 -> 209 | G13: =+F13/1.5 -> 139.33333 | H13: Falla mecanica | I13: Cambio de manguera descarga 213-135
A14: 46271 | B14: 032-083 | C14: 0.36111111 | D14: 0.42777778 | E14: 1.52 | F14: =150*E14 -> 228 | G14: =+F14/1.5 -> 152 | H14: Falla mecanica | I14: Perforación en brida ciega de manguera alimentación de la bomba 213-802 al Bm10
A15: 46272 | B15: 032-083 | C15: 0.89583333 | D15: 0.97916667 | E15: 2 | F15: =150*E15 -> 300 | G15: =+F15/1.5 -> 200 | H15: Falla mecanica | I15: Perforación en sumidero 213-233
A16: 46273 | B16: 032-204 | C16: 0.88333333 | D16: 0.088194444 | E16: 4.91 | F16: =60*E16 -> 294.6 | G16: =+F16/1.5 -> 196.4 | H16: Falla mecanica | I16: Fuga de carga bomba 213-214- cambio impulsor/cilindro.
A17: 46274 | B17: 032-204 | C17: 0.97638889 | D17: 0.0055555556 | E17: 0.7 | F17: =60*E17 -> 42 | G17: =+F17/1.5 -> 28 | H17: Falla mecanica | I17: Perforación en manguera de descarga de bomba 213-214
A18: 46275 | B18: 032-087 | C18: 0.12013889 | D18: 0.12430556 | E18: 0.1 | F18: =150*E18 -> 15 | G18: =+F18/1.5 -> 10 | H18: Falla mecanica | I18: Retiro de barretilla atravesada en malla trommel.
A19: 46276 | B19: RM01/09 | C19: 0.27777778 | D19: 0.33333333 | E19: 1.33 | F19: =1530*E19 -> 2034.9 | G19: =+F19/1.5 -> 1356.6 | H19: Falla eléctrica | I19: Corte general de energia
B20: BM01/10 | C20: 0.27777778 | D20: 0.33333333 | E20: 1.33 | F20: =1250*E20 -> 1662.5 | G20: =+F20/1.5 -> 1108.3333 | H20: Falla eléctrica | I20: Corte general de energia
A21: 46278 | B21: 032-081 | C21: 0.22916667 | D21: 0.33333333 | E21: 2.5 | F21: =200*E21 -> 500 | G21: =+F21/1.5 -> 333.33333 | H21: Falla mecanica | I21: Falla en bombas de alta del sistema lubricacion
B22: 032-083 | C22: 0.80694444 | D22: 0.99166667 | E22: 4.43 | F22: =150*E22 -> 664.5 | G22: =+F22/1.5 -> 443 | H22: Falla mecanica | I22: por perforación del sumidero 213-651.
B23: 032-083 | C23: 0.034722222 | D23: 0.28125 | E23: 5.92 | F23: =150*E23 -> 888 | G23: =+F23/1.5 -> 592 | H23: Falla mecanica | I23: por perforacion del sumidero 213-233, stand by
B24: 032-086 | C24: 0.89930556 | D24: 0.90763889 | E24: 0.2 | F24: =200*E24 -> 40 | G24: =+F24/1.5 -> 26.666667 | H24: Falla operaciones | I24: atoro en cajón de concentrado descarga sep 210-103/104.
B25: 032-087 | C25: 0.15625 | D25: 0.18402778 | E25: 0.67 | F25: =200*E25 -> 134 | G25: =+F25/1.5 -> 89.333333 | H25: Falla mecanica | I25: por parada del bolas 7
B26: 032-201 | C26: 0.22916667 | D26: 0.26111111 | E26: 0.76 | F26: =150*E26 -> 114 | G26: =+F26/1.5 -> 76 | H26: Falla mecanica | I26: parada por alarma de temperatura lado limpio
B27: 032-207 | C27: 0.15625 | D27: 0.18055556 | E27: 0.58 | F27: =150*E27 -> 87 | G27: =+F27/1.5 -> 58 | H27: Falla mecanica | I27: Falla del sistema hidrostatico bomba alta #2
B28: 032-082 | C28: 0.75347222 | D28: 0.79791667 | E28: 1.07 | F28: =+E28*200 -> 214 | G28: =+F28/1.5 -> 142.66667
B29: 032-201 | C29: 0.76458333 | D29: 0.79722222 | E29: 0.78 | H29: Falla mecanica | I29: Cambio de bomba aceite rductor y acoplr nuevo ventilador.
A30: 46279 | B30: 032-084 | C30: 0.072916667 | D30: 0.10833333 | E30: 0.85 | F30: =150*E30 -> 127.5 | G30: =+F30/1.5 -> 85 | H30: Falla mecanica | I30: Por parada del bolas 10
B31: 032-210 | C31: 0.081944444 | D31: 0.10694444 | E31: 0.77 | F31: =100*E31 -> 77 | G31: =+F31/1.5 -> 51.333333 | H31: Falla mecanica | I31: Por perforacion del canal de alimentacion
A32: 46280 | B32: 032-088 | C32: 0.85972222 | D32: 0.15763889 | E32: 7.2 | F32: =200*E32 -> 1440 | G32: =+F32/1.5 -> 960 | H32: Falla mecanica | I32: por parada del bolas 08
B33: 032-208 | C33: 0.85972222 | D33: 0.15972222 | E33: 7.2 | F33: =150*E33 -> 1080 | G33: =+F33/1.5 -> 720 | H33: Falla mecanica | I33: alta temperatura de pedestal STE
A34: 46281 | B34: 032-087 | C34: 0.21319444 | D34: 0.33333333 | E34: 2.95 | F34: =200*E34 -> 590 | G34: =+F34/1.5 -> 393.33333 | H34: Falla mecanica | I34: por parada del bolas 07
B35: 032-207 | C35: 0.1875 | D35: 0.33333333 | E35: 3.5 | F35: =150*E35 -> 525 | G35: =+F35/1.5 -> 350 | H35: Falla mecanica | I35: Baja presion de aceite bomba de alta #2, bomba #1 fuerte ruido mecanico// salida de malla reten
A36: 46284 | B36: 032-084 | C36: 0.79861111 | D36: 0.86736111 | E36: 1.65 | F36: =150*E36 -> 247.5 | G36: =+F36/1.5 -> 165 | H36: Falla mecanica | I36: por parada del bolas 10
B37: 032-210 | C37: 0.8125 | D37: 0.86319444 | E37: 0.5 | F37: =100*E37 -> 50 | G37: =+F37/1.5 -> 33.333333 | H37: Falla mecanica | I37: Retirar forro caido del interior
B38: 032-210 | C38: 0.83333333 | D38: 0.86319444 | E38: 0.72 | F38: =100*E38 -> 72 | G38: =+F38/1.5 -> 48 | H38: Falla electrica | I38: falla electrica en arranque, se subio factor de potencia
A39: 46285 | B39: 032-083 | C39: 0.4625 | D39: 0.62916667 | E39: 4 | F39: =150*E39 -> 600 | G39: =+F39/1.5 -> 400 | H39: Falla mecanica | I39: alta temperatura de pedestal STE, se rectifico peine
B40: 032-084 | C40: 0.69166667 | D40: 0.75902778 | E40: 1.62 | F40: =150*E40 -> 243 | G40: =+F40/1.5 -> 162 | H40: Falla mecanica | I40: por parada del bolas 10
B41: 032-089 | C41: 0.48611111 | D41: 0.83333333 | E41: 8.33 | F41: =220*E41 -> 1832.6 | G41: =+F41/1.5 -> 1221.7333 | H41: Falla mecanica | I41: Perdida de carga por cuello trommel
...

Sheet CONTROL CONSUMO REACTIVOS
B3: CONSUMO DE ÁCIDO OXÁLICO (KG) | G3: CONSUMO DE XANTATO (KG) | L3: CONSUMO DE ESPUMANTE
H4: Concentracion al 7 %
B5: FECHA | C5: Turno dia (12 hr) | D5: Turno noche (12 hr) | E5: Total | G5: FECHA | H5: Turno dia (12 hr) | I5: Turno noche (12 hr) | J5: Total | L5: FECHA | M5: Consumo por dia
B6: 46266 | C6: ='[1]SEPTIEMBRE 2026'!G5 -> 20000 | D6: ='[1]SEPTIEMBRE 2026'!H5 -> 16000 | E6: =SUM(C6,D6) -> 36000 | G6: =B6 -> 46266 | H6: ='[2]SEPTIEMBRE 2026'!G5 -> 3800 | I6: ='[2]SEPTIEMBRE 2026'!H5 -> 3850 | J6: =SUM(H6,I6) -> 7650 | L6: =G6 -> 46266 | M6: =[3]REACTIVOS!Z610 -> 3000
B7: 46267 | C7: ='[1]SEPTIEMBRE 2026'!G6 -> 14000 | D7: ='[1]SEPTIEMBRE 2026'!H6 -> 18000 | E7: =SUM(C7,D7) -> 32000 | G7: =B7 -> 46267 | H7: ='[2]SEPTIEMBRE 2026'!G6 -> 3850 | I7: ='[2]SEPTIEMBRE 2026'!H6 -> 3850 | J7: =SUM(H7,I7) -> 7700 | L7: =G7 -> 46267 | M7: =[3]REACTIVOS!Z611 -> 3500
B8: 46268 | C8: ='[1]SEPTIEMBRE 2026'!G7 -> 18000 | D8: ='[1]SEPTIEMBRE 2026'!H7 -> 18000 | E8: =SUM(C8,D8) -> 36000 | G8: =B8 -> 46268 | H8: ='[2]SEPTIEMBRE 2026'!G7 -> 3425 | I8: ='[2]SEPTIEMBRE 2026'!H7 -> 4250 | J8: =SUM(H8,I8) -> 7675 | L8: =G8 -> 46268 | M8: =[3]REACTIVOS!Z612 -> 3000
B9: 46269 | C9: ='[1]SEPTIEMBRE 2026'!G8 -> 20000 | D9: ='[1]SEPTIEMBRE 2026'!H8 -> 18000 | E9: =SUM(C9,D9) -> 38000 | G9: =B9 -> 46269 | H9: ='[2]SEPTIEMBRE 2026'!G8 -> 3950 | I9: ='[2]SEPTIEMBRE 2026'!H8 -> 3150 | J9: =SUM(H9,I9) -> 7100 | L9: =G9 -> 46269 | M9: =[3]REACTIVOS!Z613 -> 2500
B10: 46270 | C10: ='[1]SEPTIEMBRE 2026'!G9 -> 14000 | D10: ='[1]SEPTIEMBRE 2026'!H9 -> 14000 | E10: =SUM(C10,D10) -> 28000 | G10: =B10 -> 46270 | H10: ='[2]SEPTIEMBRE 2026'!G9 -> 3950 | I10: ='[2]SEPTIEMBRE 2026'!H9 -> 3400 | J10: =SUM(H10,I10) -> 7350 | L10: =G10 -> 46270 | M10: =[3]REACTIVOS!Z614 -> 2500
B11: 46271 | C11: ='[1]SEPTIEMBRE 2026'!G10 -> 14000 | D11: ='[1]SEPTIEMBRE 2026'!H10 -> 18000 | E11: =SUM(C11,D11) -> 32000 | G11: =B11 -> 46271 | H11: ='[2]SEPTIEMBRE 2026'!G10 -> 3900 | I11: ='[2]SEPTIEMBRE 2026'!H10 -> 3200 | J11: =SUM(H11,I11) -> 7100 | L11: =G11 -> 46271 | M11: =[3]REACTIVOS!Z615 -> 2500
B12: 46272 | C12: ='[1]SEPTIEMBRE 2026'!G11 -> 14000 | D12: ='[1]SEPTIEMBRE 2026'!H11 -> 18000 | E12: =SUM(C12,D12) -> 32000 | G12: =B12 -> 46272 | H12: ='[2]SEPTIEMBRE 2026'!G11 -> 2550 | I12: ='[2]SEPTIEMBRE 2026'!H11 -> 3850 | J12: =SUM(H12,I12) -> 6400 | L12: =G12 -> 46272 | M12: =[3]REACTIVOS!Z616 -> 2000
B13: 46273 | C13: ='[1]SEPTIEMBRE 2026'!G12 -> 16000 | D13: ='[1]SEPTIEMBRE 2026'!H12 -> 18000 | E13: =SUM(C13,D13) -> 34000 | G13: =B13 -> 46273 | H13: ='[2]SEPTIEMBRE 2026'!G12 -> 3400 | I13: ='[2]SEPTIEMBRE 2026'!H12 -> 4050 | J13: =SUM(H13,I13) -> 7450 | L13: =G13 -> 46273 | M13: =[3]REACTIVOS!Z617 -> 2500
B14: 46274 | C14: ='[1]SEPTIEMBRE 2026'!G13 -> 16000 | D14: ='[1]SEPTIEMBRE 2026'!H13 -> 20000 | E14: =SUM(C14,D14) -> 36000 | G14: =B14 -> 46274 | H14: ='[2]SEPTIEMBRE 2026'!G13 -> 4950 | I14: ='[2]SEPTIEMBRE 2026'!H13 -> 4400 | J14: =SUM(H14,I14) -> 9350 | L14: =G14 -> 46274 | M14: =[3]REACTIVOS!Z618 -> 2500
B15: 46275 | C15: ='[1]SEPTIEMBRE 2026'!G14 -> 18000 | D15: ='[1]SEPTIEMBRE 2026'!H14 -> 18000 | E15: =SUM(C15,D15) -> 36000 | G15: =B15 -> 46275 | H15: ='[2]SEPTIEMBRE 2026'!G14 -> 3150 | I15: ='[2]SEPTIEMBRE 2026'!H14 -> 3150 | J15: =SUM(H15,I15) -> 6300 | L15: =G15 -> 46275 | M15: =[3]REACTIVOS!Z619 -> 2500
B16: 46276 | C16: ='[1]SEPTIEMBRE 2026'!G15 -> 18000 | D16: ='[1]SEPTIEMBRE 2026'!H15 -> 18000 | E16: =SUM(C16,D16) -> 36000 | G16: =B16 -> 46276 | H16: ='[2]SEPTIEMBRE 2026'!G15 -> 3500 | I16: ='[2]SEPTIEMBRE 2026'!H15 -> 3150 | J16: =SUM(H16,I16) -> 6650 | L16: =G16 -> 46276 | M16: =[3]REACTIVOS!Z620 -> 2000
B17: 46277 | C17: ='[1]SEPTIEMBRE 2026'!G16 -> 0 | D17: ='[1]SEPTIEMBRE 2026'!H16 -> 18000 | E17: =SUM(C17,D17) -> 18000 | G17: =B17 -> 46277 | H17: ='[2]SEPTIEMBRE 2026'!G16 -> 350 | I17: ='[2]SEPTIEMBRE 2026'!H16 -> 3150 | J17: =SUM(H17,I17) -> 3500 | L17: =G17 -> 46277 | M17: =[3]REACTIVOS!Z621 -> 1500
... B26: 46286 | C26: ='[1]SEPTIEMBRE 2026'!G25 -> 24000 | D26: ='[1]SEPTIEMBRE 2026'!H25 -> 18000 | E26: =SUM(C26,D26) -> 42000 | G26: =B26 -> 46286 | H26: ='[2]SEPTIEMBRE 2026'!G25 -> 4400 | I26: ='[2]SEPTIEMBRE 2026'!H25 -> 3150 | J26: =SUM(H26,I26) -> 7550 | L26: =G26 -> 46286 | M26: =[3]REACTIVOS!Z630 -> 2500
B27: 46287 | C27: 22000 | D27: 18000 | E27: =SUM(C27,D27) -> 40000 | G27: =B27 -> 46287 | H27: 3150 | I27: 3150 | J27: =SUM(H27,I27) -> 6300 | L27: =G27 -> 46287 | M27: =[3]REACTIVOS!Z631 -> 2000
B28: 46288 | C28: ='[1]SEPTIEMBRE 2026'!G27 -> 20000 | D28: ='[1]SEPTIEMBRE 2026'!H27 -> 22000 | E28: =SUM(C28,D28) -> 42000 | G28: =B28 -> 46288 | H28: ='[2]SEPTIEMBRE 2026'!G27 -> 3250 | I28: ='[2]SEPTIEMBRE 2026'!H27 -> 3450 | J28: =SUM(H28,I28) -> 6700 | L28: =G28 -> 46288 | M28: =[3]REACTIVOS!Z632 -> 2000
B29: 46289 | C29: ='[1]SEPTIEMBRE 2026'!G28 -> 30000 | D29: ='[1]SEPTIEMBRE 2026'!H28 -> 24000 | E29: =SUM(C29,D29) -> 54000 | G29: =B29 -> 46289 | H29: ='[2]SEPTIEMBRE 2026'!G28 -> 4150 | I29: ='[2]SEPTIEMBRE 2026'!H28 -> 4800 | J29: =SUM(H29,I29) -> 8950 | L29: =G29 -> 46289 | M29: =[3]REACTIVOS!Z633 -> 2000
B30: 46290 | C30: ='[1]SEPTIEMBRE 2026'!G29 -> 26000 | D30: ='[1]SEPTIEMBRE 2026'!H29 -> 26000 | E30: =SUM(C30,D30) -> 52000 | G30: =B30 -> 46290 | H30: ='[2]SEPTIEMBRE 2026'!G29 -> 4000 | I30: ='[2]SEPTIEMBRE 2026'!H29 -> 4400 | J30: =SUM(H30,I30) -> 8400 | L30: =G30 -> 46290 | M30: =[3]REACTIVOS!Z634 -> 2000
B31: 46291 | C31: ='[1]SEPTIEMBRE 2026'!G30 -> 20000 | D31: ='[1]SEPTIEMBRE 2026'!H30 -> 16000 | E31: =SUM(C31,D31) -> 36000 | G31: =B31 -> 46291 | H31: ='[2]SEPTIEMBRE 2026'!G30 -> 3850 | I31: ='[2]SEPTIEMBRE 2026'!H30 -> 3150 | J31: =SUM(H31,I31) -> 7000 | L31: =G31 -> 46291 | M31: =[3]REACTIVOS!Z635 -> 2500
B32: 46292 | C32: ='[1]SEPTIEMBRE 2026'!G31 -> 24000 | D32: ='[1]SEPTIEMBRE 2026'!H31 -> 20000 | E32: =SUM(C32,D32) -> 44000 | G32: =B32 -> 46292 | H32: ='[2]SEPTIEMBRE 2026'!G31 -> 3450 | I32: ='[2]SEPTIEMBRE 2026'!H31 -> 3600 | J32: =SUM(H32,I32) -> 7050 | L32: =G32 -> 46292 | M32: =[3]REACTIVOS!Z636 -> 2500
B33: 46293 | C33: ='[1]SEPTIEMBRE 2026'!G32 -> 24000 | D33: ='[1]SEPTIEMBRE 2026'!H32 -> 20000 | E33: =SUM(C33,D33) -> 44000 | G33: =B33 -> 46293 | H33: ='[2]SEPTIEMBRE 2026'!G32 -> 3250 | I33: ='[2]SEPTIEMBRE 2026'!H32 -> 3800 | J33: =SUM(H33,I33) -> 7050 | L33: =G33 -> 46293 | M33: =[3]REACTIVOS!Z637 -> 3000
B34: 46294 | C34: ='[1]SEPTIEMBRE 2026'!G33 -> 20000 | D34: ='[1]SEPTIEMBRE 2026'!H33 -> 16000 | E34: =SUM(C34,D34) -> 36000 | G34: =B34 -> 46294 | H34: ='[2]SEPTIEMBRE 2026'!G33 -> 3600 | I34: ='[2]SEPTIEMBRE 2026'!H33 -> 3350 | J34: =SUM(H34,I34) -> 6950 | L34: =G34 -> 46294 | M34: =[3]REACTIVOS!Z638 -> 3000
B35: 46295 | C35: ='[1]SEPTIEMBRE 2026'!G34 -> 0 | D35: ='[1]SEPTIEMBRE 2026'!H34 -> 0 | E35: =SUM(C35,D35) -> 0 | G35: =B35 -> 46295 | H35: ='[2]SEPTIEMBRE 2026'!G34 -> 0 | I35: ='[2]SEPTIEMBRE 2026'!H34 -> 0 | J35: =SUM(H35,I35) -> 0 | L35: =G35 -> 46295 | M35: =[3]REACTIVOS!Z639 -> 0
B36: TOTAL | C36: =SUM(C6:C35) -> 532000 | D36: =SUM(D6:D35) -> 544000 | E36: =SUM(E6:E35) -> 1076000 | G36: TOTAL | H36: =SUM(H6:H35) -> 106075 | I36: =SUM(I6:I35) -> 107150 | J36: =SUM(J6:J35) -> 213225 | L36: TOTAL | M36: =SUM(M6:M35) -> 78000

Sheet Filtros de H20
D2: PROGRAMA DE LIMPIEZA DIARIA DE FILTROS DE H20 (CHOROS)
D4: MES: | E4: AGOSTO | F4: 2026
C6: N° | D6: FILTRO | E6: 46235 | I6: FILTRO | J6: 46267 | N6: 46268 | R6: 46269 | V6: FILTRO | W6: 46270 | AA6: 46271 | AE6: 46272
E7: 1 TURNO | F7: 2 TURNO | G7: 3 TURNO | H7: Observacion | J7: 1 TURNO | K7: 2 TURNO | L7: 3 TURNO | M7: Observacion | N7: 1 TURNO | O7: 2 TURNO | P7: 3 TURNO | Q7: Observacion | R7: 1 TURNO | S7: 2 TURNO | T7: 3 TURNO | U7: Observacion | W7: 1 TURNO | X7: 2 TURNO | Y7: 3 TURNO | Z7: Observacion | AA7: 1 TURNO | AB7: 2 TURNO | AC7: 3 TURNO | AD7: Observacion | AE7: 1 TURNO | AF7: 2 TURNO | AG7: 3 TURNO | AH7: Observacion
C8: 1 | D8: Filtro # 1 | F8: ✔ | I8: Filtro # 1 | O8: ✔ | T8: ✔ | V8: Filtro # 1 | X8: ✔ | AC8: ✔
C9: 2 | D9: Filtro # 2 | F9: ✔ | I9: Filtro # 2 | O9: ✔ | T9: ✔ | V9: Filtro # 2 | X9: ✔ | AC9: ✔
C10: 3 | D10: Filtro # 3 | F10: ✔ | I10: Filtro # 3 | O10: ✔ | T10: ✔ | V10: Filtro # 3 | X10: ✔ | AC10: ✔
C11: 4 | D11: Filtro # 4 | F11: ✖ | I11: Filtro # 4 | O11: ✖ | T11: ✖ | V11: Filtro # 4 | X11: ✖ | AC11: ✖
C12: 5 | D12: Filtro # 5 | F12: ✔ | I12: Filtro # 5 | O12: ✔ | T12: ✔ | V12: Filtro # 5 | X12: ✔ | AC12: ✔
C13: 6 | D13: Filtro Linea # 5 | F13: ✔ | I13: Filtro Linea # 5 | O13: ✔ | T13: ✔ | V13: Filtro Linea # 5 | X13: ✔ | AC13: ✔
C14: 7 | D14: Filtro Linea # 6 | F14: ✔ | I14: Filtro Linea # 6 | O14: ✔ | T14: ✔ | V14: Filtro Linea # 6 | X14: ✔ | AC14: ✔
C15: 8 | D15: Filtro Linea # 7 | F15: ✔ | I15: Filtro Linea # 7 | O15: ✔ | T15: ✔ | V15: Filtro Linea # 7 | X15: ✔ | AC15: ✔
C16: 9 | D16: Filtro Linea # 8 | F16: ✖ | I16: Filtro Linea # 8 | O16: ✖ | T16: ✖ | V16: Filtro Linea # 8 | X16: ✖ | AC16: ✖
C17: 10 | D17: Filtro Linea # 9 (01) | F17: ✔ | I17: Filtro Linea # 9 (01) | O17: ✔ | T17: ✔ | V17: Filtro Linea # 9 (01) | X17: ✔ | AC17: ✔
C18: 11 | D18: Filtro Linea # 9 (02) | F18: ✖ | I18: Filtro Linea # 9 (02) | O18: ✖ | T18: ✖ | V18: Filtro Linea # 9 (02) | X18: ✖ | AC18: ✖
D19: RESUMEN OPERACIONAL | I19: RESUMEN OPERACIONAL
D20: Filtros operativos: | F20: 8 | I20: Filtros operativos: | N20: Filtros operativos: | P20: 8 | R20: Filtros operativos: | T20: 8 | V20: Filtros operativos: | X20: 8 | AA20: Filtros operativos: | AC20: 8 | AE20: Filtros operativos:
D21: Filtros críticos: | F21: 3 | I21: Filtros críticos: | N21: Filtros críticos: | P21: 3 | R21: Filtros críticos: | T21: 3 | V21: Filtros críticos: | X21: 3 | AA21: Filtros críticos: | AC21: 3 | AE21: Filtros críticos:
D22: % CUMPLIMIENTO | F22: =F20/(F20+F21) -> 0.72727273 | I22: % CUMPLIMIENTO | N22: % CUMPLIMIENTO | P22: =+P20/11 -> 0.72727273 | R22: % CUMPLIMIENTO | T22: =+T20/11 -> 0.72727273 | V22: % CUMPLIMIENTO | X22: =+X20/11 -> 0.72727273 | AA22: % CUMPLIMIENTO | AC22: =+AC20/11 -> 0.72727273 | AE22: % CUMPLIMIENTO | AG22: =+AG20/11 -> 0
D23: Causa principal: Falla mecánica en válvulas | I23: Causa principal: Falla mecánica en válvulas | N23: Causa principal: Falla mecánica en válvulas | R23: Causa principal: Falla mecánica en válvulas | V23: Causa principal: Falla mecánica en válvulas | AA23: Causa principal: Falla mecánica en válvulas | AE23: Causa principal: Falla mecánica en válvulas
D24: Acción: Realizar mantenimiento correctivo | I24: Acción: Realizar mantenimiento correctivo | N24: Acción: Realizar mantenimiento correctivo | R24: Acción: Realizar mantenimiento correctivo | V24: Acción: Realizar mantenimiento correctivo | AA24: Acción: Realizar mantenimiento correctivo | AE24: Acción: Realizar mantenimiento correctivo
D25: Realizado por: | I25: Realizado por: | N25: Realizado por: BRIAN SALINAS | R25: Realizado por: Luis Bendezu | V25: Realizado por: Brian Salinas | AA25: Realizado por: Luis Bendezu | AE25: Realizado por:
C27: N° | D27: FILTRO | E27: 46273 | J27: 46274 | N27: 46275 | R27: 46276 | W27: 46277 | AA27: 46278 | AE27: 46279
E28: 1 TURNO | F28: 2 TURNO | G28: 3 TURNO | H28: Observacion | J28: 1 TURNO | K28: 2 TURNO | L28: 3 TURNO | M28: Observacion | N28: 1 TURNO | O28: 2 TURNO | P28: 3 TURNO | Q28: Observacion | R28: 1 TURNO | S28: 2 TURNO | T28: 3 TURNO | U28: Observacion | W28: 1 TURNO | X28: 2 TURNO | Y28: 3 TURNO | Z28: Observacion | AA28: 1 TURNO | AB28: 2 TURNO | AC28: 3 TURNO | AD28: Observacion | AE28: 1 TURNO | AF28: 2 TURNO | AG28: 3 TURNO | AH28: Observacion
C29: 1 | D29: Filtro # 1 | L29: ✔ | P29: ✔ | Z29: ✔ | AB29: ✔ | AG29: ✔
C30: 2 | D30: Filtro # 2 | L30: ✔ | P30: ✔ | Z30: ✔ | AB30: ✔ | AG30: ✔
C31: 3 | D31: Filtro # 3 | L31: ✔ | P31: ✔ | Z31: ✔ | AB31: ✔ | AG31: ✔
C32: 4 | D32: Filtro # 4 | L32: ✖ | P32: ✖ | Z32: ✖ | AB32: ✖ | AG32: ✖
C33: 5 | D33: Filtro # 5 | L33: ✔ | P33: ✔ | Z33: ✔ | AB33: ✔ | AG33: ✔
C34: 6 | D34: Filtro Linea # 5 | L34: ✔ | P34: ✔ | Z34: ✔ | AB34: ✔ | AG34: ✔
C35: 7 | D35: Filtro Linea # 6 | L35: ✔ | P35: ✔ | Z35: ✔ | AB35: ✔ | AG35: ✔
C36: 8 | D36: Filtro Linea # 7 | L36: ✔ | P36: ✔ | Z36: ✔ | AB36: ✔ | AG36: ✔
C37: 9 | D37: Filtro Linea # 8 | L37: ✖ | P37: ✖ | Z37: ✖ | AB37: ✖ | AG37: ✖
C38: 10 | D38: Filtro Linea # 9 (01) | L38: ✔ | P38: ✔ | Z38: ✔ | AB38: ✔ | AG38: ✔
C39: 11 | D39: Filtro Linea # 9 (02) | L39: ✖ | P39: ✖ | Z39: ✖ | AB39: ✖ | AG39: ✖
D40: RESUMEN OPERACIONAL
D41: Filtros operativos: | J41: Filtros operativos: | L41: 8 | N41: Filtros operativos: | P41: 8 | R41: Filtros operativos: | W41: Filtros operativos: | Y41: 8 | AA41: Filtros operativos: | AC41: 8 | AE41: Filtros operativos: | AG41: 8
D42: Filtros críticos: | J42: Filtros críticos: | L42: 3 | N42: Filtros críticos: | P42: 3 | R42: Filtros críticos: | W42: Filtros críticos: | Y42: 3 | AA42: Filtros críticos: | AC42: 3 | AE42: Filtros críticos: | AG42: 3
D43: % CUMPLIMIENTO | F43: =+F41/11 -> 0 | J43: % CUMPLIMIENTO | L43: =+L41/11 -> 0.72727273 | N43: % CUMPLIMIENTO | P43: =+P41/11 -> 0.72727273 | R43: % CUMPLIMIENTO | T43: =+T41/11 -> 0 | W43: % CUMPLIMIENTO | Y43: =+Y41/11 -> 0.72727273 | AA43: % CUMPLIMIENTO | AC43: =+AC41/11 -> 0.72727273 | AE43: % CUMPLIMIENTO | AG43: =+AG41/11 -> 0.72727273
D44: Causa principal: Falla mecánica en válvulas | J44: Causa principal: Falla mecánica en válvulas | N44: Causa principal: Falla mecánica en válvulas | R44: Causa principal: Falla mecánica en válvulas | W44: Causa principal: Falla mecánica en válvulas | AA44: Causa principal: Falla mecánica en válvulas | AE44: Causa principal: Falla mecánica en válvulas
...

Sheet CONTROL PURGA TKS AIRE 
B1: PURGA TANQUES DE AIRE COMPRIMIDO-PLANTA MAGNETICA
B3: MES: | C3: SETIEMBRE
D4: 46275 | G4: 46276 | J4: 46277 | M4: 46278
A5: I.- | B5: ID. TK. PRINCIPAL | C5: UBICACIÓN | D5: 1er Turno | E5: 2do Turno | F5: 3er Turno | G5: 1er Turno | H5: 2do Turno | I5: 3er Turno | J5: 1er Turno | K5: 2do Turno | L5: 3er Turno | M5: 1er Turno | N5: 2do Turno | O5: 3er Turno
B6: TK-MG-S. ROTULO | C6: Linea 1 | E6: ✔ | F6: ✔ | H6: ✔ | I6: ✔ | L6: ✔ | M6: ✔ | O6: ✔
B7: TK-MG-001 | C7: Linea 5 | E7: ✔ | F7: ✔ | H7: ✔ | I7: ✔ | L7: ✔ | M7: ✔ | O7: ✔
B8: TK-MG-002 | C8: Linea 8 | E8: ✔ | F8: ✔ | H8: ✔ | I8: ✔ | L8: ✔ | M8: ✔ | O8: ✔
B9: TK-MG-003 | C9: Linea 10 | E9: ✔ | F9: ✔ | H9: ✔ | I9: ✔ | L9: ✔ | M9: ✔ | O9: ✔
B10: TK-MG-005 | C10: Linea 7 | E10: X | F10: X | H10: X | I10: X | L10: X | M10: X | O10: X
B11: TK-MG-006 | C11: Linea 8 | E11: ✔ | F11: ✔ | H11: ✔ | I11: ✔ | L11: ✔ | M11: ✔ | O11: ✔
A12: II.- | B12: ID. TK. AUXILIARES | C12: UBICACIÓN
B13: TK-MG-007 | C13: MB-1 | E13: ✔ | F13: ✔ | H13: ✔ | I13: ✔ | L13: ✔ | M13: ✔ | O13: ✔
B14: TK-MG-004 | C14: MB-4 | E14: ✔ | F14: ✔ | H14: ✔ | I14: ✔ | L14: ✔ | M14: ✔ | O14: ✔
B15: TK-MG-008 | C15: MB-5 | E15: ✔ | F15: ✔ | H15: ✔ | I15: ✔ | L15: ✔ | M15: ✔ | O15: ✔
B16: TK-MG-009 | C16: MB-6 | E16: ✔ | F16: ✔ | H16: ✔ | I16: ✔ | L16: ✔ | M16: ✔ | O16: ✔
B17: TK-MG-010 | C17: MB-7 | E17: ✔ | F17: ✔ | H17: ✔ | I17: ✔ | L17: ✔ | M17: ✔ | O17: ✔
B18: TK-MG-011 | C18: MB-8 | E18: ✔ | F18: ✔ | H18: ✔ | I18: ✔ | L18: ✔ | M18: ✔ | O18: ✔
B19: TK-MG-012 | C19: MB-9 | E19: ✔ | F19: ✔ | H19: ✔ | I19: ✔ | L19: ✔ | M19: ✔ | O19: ✔
B20: TK-MG-013 | C20: RM-9 | E20: ✔ | F20: ✔ | H20: ✔ | I20: ✔ | L20: ✔ | M20: ✔ | O20: ✔
B21: TK-MG-014 | C21: MB-10 | E21: ✔ | F21: ✔ | H21: ✔ | I21: ✔ | L21: ✔ | M21: ✔ | O21: ✔
B23: * La purga de los tanques se realizara al inicio de cada guardia.
D26: 46279 | G26: 46280 | J26: 46281 | M26: 46282 | P26: 46283 | S26: 46284 | V26: 46285
A27: I.- | B27: ID. TK. PRINCIPAL | C27: UBICACIÓN | D27: 1er Turno | E27: 2do Turno | F27: 3er Turno | G27: 1er Turno | H27: 2do Turno | I27: 3er Turno | J27: 1er Turno | K27: 2do Turno | L27: 3er Turno | M27: 1er Turno | N27: 2do Turno | O27: 3er Turno | P27: 1er Turno | Q27: 2do Turno | R27: 3er Turno | S27: 1er Turno | T27: 2do Turno | U27: 3er Turno | V27: 1er Turno | W27: 2do Turno | X27: 3er Turno
A28: 1 | B28: TK-MG-S. ROTULO | C28: Linea 1 | E28: ✔ | F28: ✔ | H28: ✔ | I28: ✔ | L28: ✔ | O28: ✔ | Q28: ✔ | R28: ✔ | T28: ✔ | U28: ✔ | V28: ✔
A29: 2 | B29: TK-MG-001 | C29: Linea 5 | E29: ✔ | F29: ✔ | H29: ✔ | I29: ✔ | L29: ✔ | O29: ✔ | Q29: ✔ | R29: ✔ | T29: ✔ | U29: ✔ | V29: ✔
A30: 3 | B30: TK-MG-002 | C30: Linea 8 | E30: ✔ | F30: ✔ | H30: ✔ | I30: ✔ | L30: ✔ | O30: ✔ | Q30: ✔ | R30: ✔ | T30: ✔ | U30: ✔ | V30: ✔
A31: 4 | B31: TK-MG-003 | C31: Linea 10 | E31: ✔ | F31: ✔ | H31: ✔ | I31: ✔ | L31: ✔ | O31: ✔ | Q31: ✔ | R31: ✔ | T31: ✔ | U31: ✔ | V31: ✔
A32: 5 | B32: TK-MG-005 | C32: Linea 7 | E32: X | F32: X | H32: X | I32: X | L32: X | O32: X | Q32: X | R32: X | T32: X | U32: X | V32: X
A33: 6 | B33: TK-MG-006 | C33: Linea 8 | E33: ✔ | F33: ✔ | H33: ✔ | I33: ✔ | L33: ✔ | O33: ✔ | Q33: ✔ | R33: ✔ | T33: ✔ | U33: ✔ | V33: ✔
A34: II.- | B34: ID. TK. AUXILIARES | C34: UBICACIÓN
A35: 1 | B35: TK-MG-007 | C35: MB-1 | E35: ✔ | F35: ✔ | H35: ✔ | I35: ✔ | L35: ✔ | O35: ✔ | Q35: ✔ | R35: ✔ | T35: ✔ | U35: ✔ | V35: ✔
A36: 2 | B36: TK-MG-004 | C36: MB-4 | E36: ✔ | F36: ✔ | H36: ✔ | I36: ✔ | L36: ✔ | O36: ✔ | Q36: ✔ | R36: ✔ | T36: ✔ | U36: ✔ | V36: ✔
A37: 3 | B37: TK-MG-008 | C37: MB-5 | E37: ✔ | F37: ✔ | H37: ✔ | I37: ✔ | L37: ✔ | O37: ✔ | Q37: ✔ | R37: ✔ | T37: ✔ | U37: ✔ | V37: ✔
A38: 4 | B38: TK-MG-009 | C38: MB-6 | E38: ✔ | F38: ✔ | H38: ✔ | I38: ✔ | L38: ✔ | O38: ✔ | Q38: ✔ | R38: ✔ | T38: ✔ | U38: ✔ | V38: ✔
A39: 5 | B39: TK-MG-010 | C39: MB-7 | E39: ✔ | F39: ✔ | H39: ✔ | I39: ✔ | L39: ✔ | O39: ✔ | Q39: ✔ | R39: ✔ | T39: ✔ | U39: ✔ | V39: ✔
A40: 6 | B40: TK-MG-011 | C40: MB-8 | E40: ✔ | F40: ✔ | H40: ✔ | I40: ✔ | L40: ✔ | O40: ✔ | Q40: ✔ | R40: ✔ | T40: ✔ | U40: ✔ | V40: ✔
A41: 7 | B41: TK-MG-012 | C41: MB-9 | E41: ✔ | F41: ✔ | H41: ✔ | I41: ✔ | L41: ✔ | O41: ✔ | Q41: ✔ | R41: ✔ | T41: ✔ | U41: ✔ | V41: ✔
A42: 8 | B42: TK-MG-013 | C42: RM-9 | E42: ✔ | F42: ✔ | H42: ✔ | I42: ✔ | L42: ✔ | O42: ✔ | Q42: ✔ | R42: ✔ | T42: ✔ | U42: ✔ | V42: ✔
A43: 9 | B43: TK-MG-014 | C43: MB-10 | E43: ✔ | F43: ✔ | H43: ✔ | I43: ✔ | L43: ✔ | O43: ✔ | Q43: ✔ | R43: ✔ | T43: ✔ | U43: ✔ | V43: ✔
D46: 46286 | G46: 46287 | J46: 46288 | M46: 46289 | P46: 46290 | S46: 46291 | V46: 46292
...

Sheet LIMPIEZA SEP.MAG. COBBER
B1: CONTROL DE CUMPLIMIENTO DE LIMPIEZA INTERDIARIO DE CAJON DE ALIMENTACION – SEPARADOR MAGNETICO COBBER
B2: MES | C2: AGOSTO | D2: 2026
B3: Fecha | C3: DIA | D3: Turno | E3: 210-097 | F3: 210-098 | G3: 210-099 | H3: 210-100 | I3: 210-114 | J3: 210-115 | K3: 210-101 | L3: 210-102 | M3: 210-103 | N3: 210-104 | O3: 210-105 | P3: 210-106 | Q3: 210-107 | R3: 210-108 | S3: 210-268 | T3: 210-269 | U3: Ejecutados | V3: No ejecutados | W3: Cumplimiento | X3: Estado | Y3: Observacion
B4: 46030 | C4: Sabado | D4: 1° Turno | U4: 0 | V4: 16 | W4: 0 | X4: DEFICIENTE
B5: 46061 | C5: Domingo | D5: 1° Turno | U5: 8 | V5: 8 | W5: 0.5 | X5: DEFICIENTE
B6: 46089 | C6: Lunes | D6: 1° Turno | U6: 0 | V6: 16 | W6: 0 | X6: DEFICIENTE
B7: 46120 | C7: Martes | D7: 1° Turno | U7: 12 | V7: 4 | W7: =+U7/16 -> 0.75
B8: 46150 | C8: Miercoles | D8: 1° Turno | U8: 0 | V8: 16 | W8: 0 | X8: DEFICIENTE
B9: 46181 | C9: Jueves | D9: 1° Turno | U9: 0 | V9: 16 | W9: 0 | X9: DEFICIENTE
B10: 46211 | C10: Viernes | D10: 1° Turno | U10: 13 | V10: 3 | W10: =+U10/16 -> 0.8125
B11: 46242 | C11: Sabado | D11: 1° Turno | U11: 0 | V11: 16 | W11: 0 | X11: DEFICIENTE
B12: 46273 | C12: Domingo | D12: 1° Turno | U12: 0 | V12: 16 | W12: 0 | X12: DEFICIENTE
B13: 46303 | C13: Lunes | D13: 1° Turno | U13: 13 | V13: 3 | W13: =+U13/16 -> 0.8125
B14: 46334 | C14: Martes | D14: 1° Turno | U14: 0 | V14: 16 | W14: =+U14/16 -> 0 | X14: DEFICIENTE
B15: 46364 | C15: Miercoles | D15: 1° Turno | U15: 0 | V15: 16 | W15: 0 | X15: DEFICIENTE
B16: 13/8/2027 | C16: Jueves | D16: 1° Turno | U16: 13 | V16: 3 | W16: =+U16/16 -> 0.8125
B17: 14/8/2027 | C17: Viernes | D17: 1° Turno | U17: 0 | V17: 16 | W17: =+U17/16 -> 0 | X17: DEFICIENTE
B18: 15/8/2027 | C18: Sabado | D18: 1° Turno | U18: 0 | V18: 16 | W18: 0 | X18: DEFICIENTE
B19: 16/8/2027 | C19: Domingo | D19: 1° Turno | U19: 3 | V19: 13 | W19: =+U19/16 -> 0.1875 | X19: DEFICIENTE
B20: 17/8/2027 | C20: Lunes | D20: 1° Turno | U20: 0 | V20: 16 | W20: =+U20/16 -> 0 | X20: DEFICIENTE
B21: 18/8/2027 | C21: Martes | D21: 1° Turno | U21: 0 | V21: 16 | W21: =+U21/16 -> 0 | X21: DEFICIENTE
B22: 19/8/2027 | C22: Miercoles | D22: 1° Turno | U22: 0 | V22: 16 | W22: =+U22/16 -> 0 | X22: DEFICIENTE
B23: 20/8/2027 | C23: Jueves | D23: 1° Turno | U23: 14 | V23: 2 | W23: =+U23/16 -> 0.875
B24: 21/8/2027 | C24: Viernes | D24: 1° Turno | U24: 0 | V24: 16 | W24: =+U24/16 -> 0 | X24: DEFICIENTE
B25: 22/8/2028 | C25: Sabado | D25: 1° Turno | U25: 14 | V25: =16-U25 -> 2 | W25: =+U25/16 -> 0.875
B26: 23/8/2028 | C26: Domingo | D26: 2° Turno | U26: 0 | V26: 0 | W26: 0 | X26: DEFICIENTE
B27: 24/8/2028 | C27: Lunes | D27: 1° Turno
B28: 25/8/2028 | C28: Martes | D28: 1° Turno
B29: 26/8/2028 | C29: Miercoles | D29: 1° Turno
B30: 27/8/2027 | C30: Jueves | D30: 1° Turno
B31: 28/8/2027 | C31: Viernes | D31: 1° Turno
B32: 29/8/2028 | C32: Sabado | D32: 1° Turno
B33: 30/8/2028 | C33: Domingo | D33: 1° Turno
B34: 31/8/2028 | C34: Lunes | D34: 1° Turno

Sheet TONELADAS X TURNO
B1: Molino barras 1 | E1: Molino barras 2 | H1: Molino barras 3 | K1: Molino barras 4 | N1: Molino barras 5 | Q1: Molino barras 6 | T1: Molino barras 7 | W1: Molino barras 8 | Z1: Molino barras 9
A2: Fecha | B2: 1° turno | C2: 2° turno | D2: 3° turno | E2: 1° turno | F2: 2° turno | G2: 3° turno | H2: 1° turno | I2: 2° turno | J2: 3° turno | K2: 1° turno | L2: 2° turno | M2: 3° turno | N2: 1° turno | O2: 2° turno | P2: 3° turno | Q2: 1° turno | R2: 2° turno | S2: 3° turno | T2: 1° turno | U2: 2° turno | V2: 3° turno | W2: 1° turno | X2: 2° turno | Y2: 3° turno | Z2: 1° turno | AA2: 2° turno | AB2: 3° turno
